2017-12-24 13:59:31,568 - memeMaker - INFO - program beginning execution at 2017-12-24 13:59:31.568347
2017-12-24 13:59:31,568 - memeMaker - INFO - Parsing JSON data
2017-12-24 13:59:31,568 - memeMaker - INFO - JSON data parsed
2017-12-24 13:59:31,568 - memeMaker - INFO - populating meme tweets and pic URL lists
2017-12-24 13:59:38,025 - memeMaker - INFO - loaded data file <_io.TextIOWrapper name='memeData1218To1219' mode='r' encoding='cp1252'>
2017-12-24 13:59:57,966 - memeMaker - ERROR - exception hit
Traceback (most recent call last):
  File "C:\Users\Derek\PostGradProjects\MemeMaker\JSONParser.py", line 27, in parseMemes
    if(detect(s) == 'en'):
  File "D:\Users\Derek\AppData\local\Programs\Python\Python36\lib\site-packages\langdetect\detector_factory.py", line 130, in detect
    return detector.detect()
  File "D:\Users\Derek\AppData\local\Programs\Python\Python36\lib\site-packages\langdetect\detector.py", line 136, in detect
    probabilities = self.get_probabilities()
  File "D:\Users\Derek\AppData\local\Programs\Python\Python36\lib\site-packages\langdetect\detector.py", line 143, in get_probabilities
    self._detect_block()
  File "D:\Users\Derek\AppData\local\Programs\Python\Python36\lib\site-packages\langdetect\detector.py", line 150, in _detect_block
    raise LangDetectException(ErrorCode.CantDetectError, 'No features in text.')
langdetect.lang_detect_exception.LangDetectException: No features in text.
2017-12-24 13:59:58,475 - memeMaker - INFO - lists successfully populate
2017-12-24 13:59:58,475 - memeMaker - INFO - making memes
2017-12-24 14:00:00,975 - memeMaker - ERROR - Failed to create and open memePage for )pic.twitter.com/7LXjBTRKvw
Traceback (most recent call last):
  File "C:\Users\Derek\PostGradProjects\MemeMaker\MemeCompiler.py", line 47, in memeMaker
    img = urllib.request.urlopen(req)
  File "D:\Users\Derek\AppData\local\Programs\Python\Python36\lib\urllib\request.py", line 223, in urlopen
    return opener.open(url, data, timeout)
  File "D:\Users\Derek\AppData\local\Programs\Python\Python36\lib\urllib\request.py", line 532, in open
    response = meth(req, response)
  File "D:\Users\Derek\AppData\local\Programs\Python\Python36\lib\urllib\request.py", line 642, in http_response
    'http', request, response, code, msg, hdrs)
  File "D:\Users\Derek\AppData\local\Programs\Python\Python36\lib\urllib\request.py", line 564, in error
    result = self._call_chain(*args)
  File "D:\Users\Derek\AppData\local\Programs\Python\Python36\lib\urllib\request.py", line 504, in _call_chain
    result = func(*args)
  File "D:\Users\Derek\AppData\local\Programs\Python\Python36\lib\urllib\request.py", line 756, in http_error_302
    return self.parent.open(new, timeout=req.timeout)
  File "D:\Users\Derek\AppData\local\Programs\Python\Python36\lib\urllib\request.py", line 532, in open
    response = meth(req, response)
  File "D:\Users\Derek\AppData\local\Programs\Python\Python36\lib\urllib\request.py", line 642, in http_response
    'http', request, response, code, msg, hdrs)
  File "D:\Users\Derek\AppData\local\Programs\Python\Python36\lib\urllib\request.py", line 570, in error
    return self._call_chain(*args)
  File "D:\Users\Derek\AppData\local\Programs\Python\Python36\lib\urllib\request.py", line 504, in _call_chain
    result = func(*args)
  File "D:\Users\Derek\AppData\local\Programs\Python\Python36\lib\urllib\request.py", line 650, in http_error_default
    raise HTTPError(req.full_url, code, msg, hdrs, fp)
urllib.error.HTTPError: HTTP Error 415: UNSUPPORTED MEDIA TYPE
2017-12-24 14:00:03,545 - memeMaker - ERROR - Failed to create and open memePage for pic.twitter.com/RmEQgGDOVT
Traceback (most recent call last):
  File "C:\Users\Derek\PostGradProjects\MemeMaker\MemeCompiler.py", line 39, in memeMaker
    nonTwitterURL = picURLParser(URL)
  File "C:\Users\Derek\PostGradProjects\MemeMaker\MemeCompiler.py", line 24, in picURLParser
    URL = link.attrs['src'] #getting the wrong picture, gotta think about this some more
AttributeError: 'NoneType' object has no attribute 'attrs'
2017-12-24 14:00:03,560 - memeMaker - ERROR - Failed to create and open memePage for http://women.ncr-iran.org/iran-women-news/4553-iran-young-women-actively-partake-in-student-protests …pic.twitter.com/TjnzkCPJ7Q
Traceback (most recent call last):
  File "C:\Users\Derek\PostGradProjects\MemeMaker\MemeCompiler.py", line 47, in memeMaker
    img = urllib.request.urlopen(req)
  File "D:\Users\Derek\AppData\local\Programs\Python\Python36\lib\urllib\request.py", line 223, in urlopen
    return opener.open(url, data, timeout)
  File "D:\Users\Derek\AppData\local\Programs\Python\Python36\lib\urllib\request.py", line 526, in open
    response = self._open(req, data)
  File "D:\Users\Derek\AppData\local\Programs\Python\Python36\lib\urllib\request.py", line 544, in _open
    '_open', req)
  File "D:\Users\Derek\AppData\local\Programs\Python\Python36\lib\urllib\request.py", line 504, in _call_chain
    result = func(*args)
  File "D:\Users\Derek\AppData\local\Programs\Python\Python36\lib\urllib\request.py", line 1361, in https_open
    context=self._context, check_hostname=self._check_hostname)
  File "D:\Users\Derek\AppData\local\Programs\Python\Python36\lib\urllib\request.py", line 1318, in do_open
    encode_chunked=req.has_header('Transfer-encoding'))
  File "D:\Users\Derek\AppData\local\Programs\Python\Python36\lib\http\client.py", line 1239, in request
    self._send_request(method, url, body, headers, encode_chunked)
  File "D:\Users\Derek\AppData\local\Programs\Python\Python36\lib\http\client.py", line 1250, in _send_request
    self.putrequest(method, url, **skips)
  File "D:\Users\Derek\AppData\local\Programs\Python\Python36\lib\http\client.py", line 1117, in putrequest
    self._output(request.encode('ascii'))
UnicodeEncodeError: 'ascii' codec can't encode character '\u2026' in position 68: ordinal not in range(128)
2017-12-24 14:00:07,515 - memeMaker - ERROR - Failed to create and open memePage for (https://instagram.com/p/Bc2tT6NnFfq/ )pic.twitter.com/wMiHqDyIQQ
Traceback (most recent call last):
  File "C:\Users\Derek\PostGradProjects\MemeMaker\MemeCompiler.py", line 47, in memeMaker
    img = urllib.request.urlopen(req)
  File "D:\Users\Derek\AppData\local\Programs\Python\Python36\lib\urllib\request.py", line 223, in urlopen
    return opener.open(url, data, timeout)
  File "D:\Users\Derek\AppData\local\Programs\Python\Python36\lib\urllib\request.py", line 526, in open
    response = self._open(req, data)
  File "D:\Users\Derek\AppData\local\Programs\Python\Python36\lib\urllib\request.py", line 544, in _open
    '_open', req)
  File "D:\Users\Derek\AppData\local\Programs\Python\Python36\lib\urllib\request.py", line 504, in _call_chain
    result = func(*args)
  File "D:\Users\Derek\AppData\local\Programs\Python\Python36\lib\urllib\request.py", line 1361, in https_open
    context=self._context, check_hostname=self._check_hostname)
  File "D:\Users\Derek\AppData\local\Programs\Python\Python36\lib\urllib\request.py", line 1318, in do_open
    encode_chunked=req.has_header('Transfer-encoding'))
  File "D:\Users\Derek\AppData\local\Programs\Python\Python36\lib\http\client.py", line 1239, in request
    self._send_request(method, url, body, headers, encode_chunked)
  File "D:\Users\Derek\AppData\local\Programs\Python\Python36\lib\http\client.py", line 1250, in _send_request
    self.putrequest(method, url, **skips)
  File "D:\Users\Derek\AppData\local\Programs\Python\Python36\lib\http\client.py", line 1117, in putrequest
    self._output(request.encode('ascii'))
UnicodeEncodeError: 'ascii' codec can't encode character '\xa0' in position 110: ordinal not in range(128)
